Workbook

Sheet RESUMEN
A1: TRAMO_INI | B1: (Varios elementos)
A3: Suma de SALDO_INSOLUTO_INI | B3: Etiquetas de columna
A4: Etiquetas de fila | B4: CASTIGO | C4: VIGENTE | D4: Total general
A5: Apr | B5: 98266240 | C5: 2254105721 | D5: 2352371961
A6: Jun | B6: 1607206191 | D6: 1607206191
A7: Total general | B7: 1705472431 | C7: 2254105721 | D7: 3959578152
A10: TRAMO_INI | B10: (Varios elementos)
A12: Cuenta de SALDO_INSOLUTO_INI | B12: Etiquetas de columna
A13: Etiquetas de fila | B13: CASTIGO | C13: VIGENTE | D13: Total general
A14: Apr | B14: 9 | C14: 302 | D14: 311
A15: Jun | B15: 171 | D15: 171
A16: Total general | B16: 180 | C16: 302 | D16: 482
A20: Cuenta de SALDO_INSOLUTO_INI | B20: Etiquetas de columna | E20: Suma de SALDO_INSOLUTO_INI | F20: Etiquetas de columna
A21: Etiquetas de fila | B21: CASTIGO | C21: VIGENTE | D21: Total general | E21: Etiquetas de fila | F21: CASTIGO | G21: VIGENTE | H21: Total general
A22: Apr | B22: 9 | C22: 302 | D22: 311 | E22: Apr | F22: 98266240 | G22: 2254105721 | H22: 2352371961
A23: 0-365 | B23: 9 | D23: 9 | E23: 0-365 | F23: 98266240 | H23: 98266240
A24: 121-150 | C24: 24 | D24: 24 | E24: 121-150 | G24: 211511353 | H24: 211511353
A25: 151-180 | C25: 39 | D25: 39 | E25: 151-180 | G25: 270077139 | H25: 270077139
A26: 181-210 | C26: 31 | D26: 31 | E26: 181-210 | G26: 235826485 | H26: 235826485
A27: 211-240 | C27: 21 | D27: 21 | E27: 211-240 | G27: 264288632 | H27: 264288632
A28: 241-270 | C28: 30 | D28: 30 | E28: 241-270 | G28: 236386021 | H28: 236386021
A29: 271-300 | C29: 25 | D29: 25 | E29: 271-300 | G29: 170650233 | H29: 170650233
A30: 301-330 | C30: 21 | D30: 21 | E30: 301-330 | G30: 162708140 | H30: 162708140
A31: 31-60 | C31: 41 | D31: 41 | E31: 31-60 | G31: 261949003 | H31: 261949003
A32: 331-360 | C32: 13 | D32: 13 | E32: 331-360 | G32: 92105312 | H32: 92105312
A33: 361-390 | C33: 4 | D33: 4 | E33: 361-390 | G33: 30915537 | H33: 30915537
A34: 61-90 | C34: 37 | D34: 37 | E34: 61-90 | G34: 196467819 | H34: 196467819
A35: 91-120 | C35: 16 | D35: 16 | E35: 91-120 | G35: 121220047 | H35: 121220047
A36: Jun | B36: 171 | D36: 171 | E36: Jun | F36: 1607206191 | H36: 1607206191
A37: Total general | B37: 180 | C37: 302 | D37: 482 | E37: Total general | F37: 1705472431 | G37: 2254105721 | H37: 3959578152

Sheet Export
A1: ID_CREDITO | B1: DIAS_MORA | C1: CUOTAS_MOROSAS_ACTUAL | D1: SALDO_INSOLUTO_INI | E1: PRIORIDAD_GESTION | F1: GESTOR | G1: TIPO_COBRANZA | H1: TRAMO_INI | I1: TRAMO_ACT | J1: TIPO_CARTERA | K1: TIPO_GESTION | L1: FECHA_ASIGNACION | M1: SEGMENTO_CLIENTE | N1: RUT | O1: DV | P1: RAZON_SOCIAL | Q1: PERSONA_NATURAL | R1: VALOR_CUOTA | S1: FECHA_PROX_VCTO | T1: CUOTAS_PAGADAS_ACTUAL | U1: CUOTAS_PAGADAS_INI | V1: PLAZO | W1: CANAL_VENTA | X1: CAMPANAS | Y1: INT_MORA_TOTAL | Z1: GC_TOTAL | AA1: ESTADO_PAT_PAC | AB1: FECHA_FIRMA_PAGARE | AC1: MONTO_ADEUDADO | AD1: TASA_INTERES_CRED | AE1: CONVENIO_CASTIGO | AF1: GESTOR_PLAN_PAGO | AG1: MARCA_CLIENTE | AH1: ESTADO_COBRANZA | AI1: TELEFONO_1 | AJ1: TELEFONO_2 | AK1: TELEFONO_3 | AL1: EMAIL_1 | AM1: EMAIL_2 | AN1: EMAIL_3 | AO1: DIRECCION | AP1: COMUNA | AQ1: REGION | AR1: ROL | AS1: TRIBUNAL | AT1: ESTADO_JUDICIAL | AU1: TIPO_JUDICIAL | AV1: DUAL | AW1: SUSP_ESTADO_JUDICIAL | AX1: SUSP_MOTIVO | AY1: SUSP_FECHA | AZ1: NOTIFICADO | BA1: ESTADO_JUICIO | BB1: VEHICULO_1_PATENTE | BC1: VEHICULO_1_MARCA | BD1: VEHICULO_1_MODELO | BE1: VEHICULO_1_ANIO | BF1: VEHICULO_1_ANIO
A2: 134218 | B2: 3638 | D2: 9957095 | F2: PHOENIX | G2: JUDICIAL | H2: 1096+ | I2: 1096+ | J2: CASTIGO | K2: COBRANZA | L2: 46180 | N2: 12269228 | O2: 0 | P2: CLAUDIO GERMAN ALEGRIA GONZALEZ | R2: 331.459 | S2: 31-07-2016 | W2: TANNER | X2: DACIÓN | Y2: 0 | Z2: 0 | AC2: 5018962 | AH2: CASTIGO | AI2: 09 7 2632839 | AL2: CALEGRIA193@GMAIL.COM | AO2: AV LA HACIENDA N 2776 | AP2: LAMPA | AQ2: REGION METROPOLITANA | AR2: SIN ROL | AS2: SIN TRIBUNAL | AT2: ASIGNACION | AU2: MANTIENE | AV2: NULL | AZ2: NO | BA2: ACTIVO | BB2: DFBY26 | BC2: MITSUBISHI | BD2: L-200 | BE2: 2012 | BF2: 2012
A3: 585590 | B3: 1081 | D3: 5293774 | F3: PHOENIX | G3: JUDICIAL | H3: 731-1095 | I3: 731-1095 | J3: CASTIGO | K3: COBRANZA | L3: 46180 | N3: 14191047 | O3: 7 | P3: FRANCISCO JAVIER LEPIN NEICO | R3: 232.332 | S3: 44934 | W3: TANNER | Y3: 0 | Z3: 0 | AC3: 2393774 | AH3: CASTIGO | AI3: 988631685 | AL3: F.LEPIN@PROFESOR.DUOC.CL | AO3: TUCAPEL JIMENEZ | AP3: SANTIAGO | AQ3: REGION METROPOLITANA | AR3: C-5981-2020 | AS3: 24° Juzgado Civil de Santiago | AT3: REMATADO | AU3: MANTIENE | AZ3: SI | BA3: ACTIVO | BB3: HRJF70 | BC3: KIA MOTORS | BD3: RIO 5 EX 1.4 | BE3: 2016 | BF3: 2016
A4: 1344919 | B4: 411 | D4: 6716000 | F4: PHOENIX | G4: JUDICIAL | H4: 366-730 | I4: 366-730 | J4: CASTIGO | K4: COBRANZA | L4: 46180 | N4: 16746764 | O4: 4 | P4: GERALDINE KAROL VIVAR ARGOMEDO | R4: 292.847 | S4: 45663 | W4: TANNER | X4: DACIÓN | Y4: 0 | Z4: 0 | AC4: 6716000 | AH4: CASTIGO | AI4: 999134883 | AL4: gvivar20@gmail.com | AO4: DECIMA AVENIDA 1430 | AP4: SAN MIGUEL | AQ4: REGION METROPOLITANA | AR4: C-19084-2024 | AS4: 19º Juzgado Civil de Santiago | AT4: EMBARGADO | AU4: MANTIENE | AZ4: SI | BA4: ACTIVO | BB4: PTSS82 | BC4: OPEL | BD4: CROSSLAND TD MT6 1.5 | BE4: 2021 | BF4: 2021
A5: 1371362 | B5: 381 | D5: 8434800 | F5: PHOENIX | G5: JUDICIAL | H5: 366-730 | I5: 366-730 | J5: CASTIGO | K5: COBRANZA | L5: 46180 | N5: 17777736 | O5: 6 | P5: MATIAS IGNACIO RIVEROS ORREGO RIVEROS ORREGO | R5: 486.859 | S5: 45664 | W5: TANNER | X5: DACIÓN | Y5: 0 | Z5: 0 | AC5: 8434800 | AH5: CASTIGO | AI5: 228544308 | AL5: matias.ro@hotmail.com | AO5: HERIBERTO COBARRUBIAS 679 | AP5: ÑUÑOA | AQ5: REGION METROPOLITANA | AR5: C-20304-2024 | AS5: 28º Juzgado Civil de Santiago | AT5: NOTIFICADO | AU5: MANTIENE | AZ5: SI | BA5: ACTIVO | BB5: PYCC10 | BC5: MAZDA | BD5: ALL NEW CX-30 GTX 2.0 2WD 6AT 7G | BE5: 2021 | BF5: 2021
A6: 1421319 | B6: 411 | D6: 4230316 | F6: PHOENIX | G6: JUDICIAL | H6: 366-730 | I6: 366-730 | J6: CASTIGO | K6: COBRANZA | L6: 46180 | N6: 9386766 | O6: 1 | P6: AVELINO DEL TRÁNSITO REYES ESCOBAR | R6: 283.17 | S6: 45663 | W6: TANNER | X6: DACIÓN | Y6: 0 | Z6: 0 | AC6: 4230316 | AH6: CASTIGO | AI6: 998656951 | AL6: avelinoreyesescobar@gmail.com | AO6: Calle Ictinos 1663 | AP6: PEÑALOLEN | AQ6: REGION METROPOLITANA | AR6: C-19072-2024 | AS6: 8º JUZGADO CIVIL DE SANTIAGO | AT6: INGRESADO | AU6: MANTIENE | AZ6: NO | BA6: ACTIVO | BB6: RBDK38 | BC6: JETOUR | BD6: X70 1.5 AUT | BE6: 2021 | BF6: 2021
A7: 1444864 | B7: 411 | D7: 5112777 | F7: PHOENIX | G7: JUDICIAL | H7: 366-730 | I7: 366-730 | J7: CASTIGO | K7: COBRANZA | L7: 46180 | N7: 18135936 | O7: 6 | P7: MILKO ANDRÉS VALLADARES ASTUDILLO | R7: 207.859 | S7: 45663 | W7: TANNER | X7: DACIÓN | Y7: 0 | Z7: 0 | AC7: 5112777 | AH7: CASTIGO | AI7: 956375289 | AL7: milkovalladares1@gmail.com | AO7: ALMIRANTE SIMSON, 1218 | AP7: LOTA | AQ7: VIII REGION | AR7: C-19069-2024 | AS7: 16º Juzgado Civil de Santiago | AT7: EMBARGADO | AU7: MANTIENE | AZ7: SI | BA7: ACTIVO | BB7: RHHH87 | BC7: HAVAL | BD7: HAVAL JOLION 1.5T MT 4X2 ACTIVE | BE7: 2022 | BF7: 2022
A8: 1446743 | B8: 319 | D8: 3879999 | F8: PHOENIX | G8: JUDICIAL | H8: 0-365 | I8: 0-365 | J8: CASTIGO | K8: COBRANZA | L8: 46180 | N8: 14463964 | O8: 2 | P8: MARCELO ALEJANDRO MELLADO SÁNCHEZ | R8: 260.396 | S8: 45666 | W8: CREDINISSAN | X8: DACIÓN | Y8: 0 | Z8: 0 | AC8: 3879999 | AH8: CASTIGO | AI8: 964062894 | AL8: PATHY_JANA86@HOTMAIL.COM | AO8: TALCA 161 | AP8: OSORNO | AQ8: X REGION | AR8: C-22129-2024 | AS8: 15º Juzgado Civil de Santiago | AT8: INGRESADO | AU8: MANTIENE | AZ8: NO | BA8: ACTIVO | BB8: RBYP22 | BC8: NISSAN | BD8: KICKS 1.6 | BE8: 2021 | BF8: 2021
A9: 1447663 | B9: 442 | D9: 8889221 | F9: PHOENIX | G9: JUDICIAL | H9: 366-730 | I9: 366-730 | J9: CASTIGO | K9: COBRANZA | L9: 46180 | N9: 12756661 | O9: 5 | P9: RODRIGO HERNÁN COVARRUBIAS NANNIG | R9: 337.74 | S9: 45662 | W9: TANNER | X9: DACIÓN | Y9: 0 | Z9: 0 | AC9: 8889221 | AH9: CASTIGO | AI9: 995471634 | AL9: rodrigo.covarrubias75@gmail.com | AO9: PASAJE VALENZUELA 75 | AP9: FRUTILLAR | AQ9: X REGION | AR9: C-19067-2024 | AS9: 5º Juzgado Civil de Santiago | AT9: EMBARGADO | AU9: MANTIENE | AZ9: SI | BA9: ACTIVO | BB9: PZTC67 | BC9: OPEL | BD9: GRANDLAND 1.6 AUT | BE9: 2021 | BF9: 2021
A10: 1479919 | B10: 258 | D10: 4032000 | F10: PHOENIX | G10: JUDICIAL | H10: 0-365 | I10: 0-365 | J10: CASTIGO | K10: COBRANZA | L10: 46180 | N10: 8878648 | O10: 3 | P10: JORGE ORLANDO CIFUENTES LARA CIFUENTES LARA | R10: 209.325 | S10: 45668 | W10: TANNER | X10: DACIÓN | Y10: 0 | Z10: 0 | AC10: 4032000 | AH10: CASTIGO | AI10: 997950973 | AL10: YOHAIROCIFUENTES@GMAIL.COM | AO10: PASAJE ANCALLE 0372 | AP10: TEMUCO | AQ10: IX REGION | AR10: C-3900-2025 | AS10: 2º Juzgado Civil de Santiago | AT10: INGRESADO | AU10: MANTIENE | AZ10: NO | BA10: ACTIVO | BB10: RBRC21 | BC10: CHANGAN | BD10: NEW CS15 ELITE HB 1.5 AUT | BE10: 2021 | BF10: 2021
A11: 1493544 | B11: 228 | D11: 10161255 | F11: PHOENIX | G11: JUDICIAL | H11: 0-365 | I11: 0-365 | J11: CASTIGO | K11: COBRANZA | L11: 46180 | N11: 15621497 | O11: 3 | P11: PAULINA ANDREA HENRÍQUEZ TELLO | R11: 497.856 | S11: 45669 | W11: TANNER | X11: DACIÓN | Y11: 0 | Z11: 0 | AC11: 10161255 | AH11: CASTIGO | AI11: 968731785 | AL11: PHENRIQUEZTELLO@GMAIL.COM | AO11: Lomas de Catapilco sito 58, Zapallar | AP11: ZAPALLAR | AQ11: V REGION | AR11: C-3900-2025 | AS11: 27º Juzgado Civil de Santiago | AT11: EMBARGADO | AU11: MANTIENE | AZ11: SI | BA11: ACTIVO | BB11: KVJW91 | BC11: PEUGEOT | BD11: 3008 GT LINE 1.6 | BE11: 2019 | BF11: 2019
A12: 1494440 | B12: 138 | D12: 3819552 | F12: PHOENIX | G12: JUDICIAL | H12: 0-365 | I12: 0-365 | J12: CASTIGO | K12: COBRANZA | L12: 46180 | M12: E | N12: 14085342 | O12: 9 | P12: MIGUEL ANGEL VERA LOPEZ | R12: 155.319 | S12: 46025 | W12: TANNER | X12: DACIÓN | Y12: 0 | Z12: 0 | AC12: 3819552 | AH12: CASTIGO | AI12: 978991743 | AL12: ANGEL.VERA.LOPEZ797@GMAIL.COM | AO12: BILBAO 654 | AP12: OSORNO | AQ12: X REGION | AR12: C-8325-2025 | AS12: 20º Juzgado Civil de Santiago | AT12: EMBARGADO | AU12: MANTIENE | AZ12: SI | BA12: ACTIVO | BB12: RFVK52 | BC12: JAC | BD12: JS2 1.5 | BE12: 2022 | BF12: 2022
A13: 1524638 | B13: 228 | D13: 3499999 | F13: PHOENIX | G13: JUDICIAL | H13: 0-365 | I13: 0-365 | J13: CASTIGO | K13: COBRANZA | L13: 46180 | N13: 12712897 | O13: 9 | P13: DENISE DE LOURDES ARTEAGA GÓMEZ | R13: 358.441 | S13: 45669 | W13: CREDINISSAN | X13: DACIÓN | Y13: 0 | Z13: 0 | AC13: 2624999 | AE13: PUT EN CUOTAS | AF13: PHOENIX | AH13: CASTIGO | AI13: 998656256 | AL13: DENISEARTEAGA@GMAIL.COM | AO13: SANTA INES 1060 | AP13: PUERTO MONTT | AQ13: X REGION | AR13: C-19078-2024 | AS13: 26º Juzgado Civil de Santiago | AT13: INGRESADO | AU13: MANTIENE | AZ13: NO | BA13: ACTIVO | BB13: RHPP76 | BC13: NISSAN | BD13: X TRAIL CVT 2.5 AT | BE13: 2022 | BF13: 2022
A14: 1530466 | B14: 411 | D14: 4391250 | F14: PHOENIX | G14: JUDICIAL | H14: 366-730 | I14: 366-730 | J14: CASTIGO | K14: COBRANZA | L14: 46180 | N14: 15741073 | O14: 3 | P14: YANIRA ANDREA CHELMES ARAYA | R14: 201.502 | S14: 45663 | W14: TANNER | X14: DACIÓN | Y14: 0 | Z14: 0 | AC14: 4391250 | AH14: CASTIGO | AI14: 948905338 | AL14: YANIRACHELMES38@GMAIL.COM | AO14: PUERTO VARAS 1144 | AP14: COQUIMBO | AQ14: IV REGION | AR14: C-19095-2024 | AS14: 30º JUZGADO CIVIL DE SANTIAGO | AT14: EMBARGADO | AU14: MANTIENE | AW14: TERMINADO | AX14: PAGO TOTAL | AY14: 13-07-2026 | AZ14: SI | BA14: CERRADO | BB14: RHZV90 | BC14: JAC | BD14: JS2 1.5 | BE14: 2021 | BF14: 2021
A15: 1540238 | B15: 77 | D15: 6394950 | F15: PHOENIX | G15: JUDICIAL | H15: 0-365 | I15: 0-365 | J15: CASTIGO | K15: COBRANZA | L15: 46180 | M15: E | N15: 16552562 | O15: 0 | P15: GUILLERMO ANDRES BAHAMONDES LORCA | R15: 344.325 | S15: 46027 | W15: TANNER | X15: DACIÓN | Y15: 0 | Z15: 0 | AC15: 6394950 | AH15: CASTIGO | AI15: 948571269 | AL15: GUILLERMOBAHAMONDESLORCA@GMAIL.COM | AO15: LOS ATACAMEÑOS 2577 | AP15: RENCA | AQ15: REGION METROPOLITANA | AR15: C-20327-2024 | AS15: 23º JUZGADO CIVIL DE SANTIAGO | AT15: EMBARGADO | AU15: MANTIENE | AZ15: SI | BA15: ACTIVO | BB15: RFYY61 | BC15: RENAULT | BD15: OROCH OTTO 2.0 | BE15: 2022 | BF15: 2022
A16: 1542074 | B16: 319 | D16: 6733739 | F16: PHOENIX | G16: JUDICIAL | H16: 0-365 | I16: 0-365 | J16: CASTIGO | K16: COBRANZA | L16: 46180 | N16: 10887679 | O16: 4 | P16: ELIZABETH CRISTINA ROSALES HEREDIA | R16: 268.871 | S16: 45666 | W16: CREDINISSAN | X16: DACIÓN | Y16: 0 | Z16: 0 | AC16: 6733739 | AH16: CASTIGO | AI16: 995635971 | AL16: ELITA.ROSA@HOTMAIL.COM | AO16: PASAJE RIO BLANCO 1376 | AP16: COQUIMBO | AQ16: IV REGION | AR16: C-20314-2024 | AS16: 9º Juzgado Civil de Santiago | AT16: INGRESADO | AU16: MANTIENE | AZ16: NO | BA16: ACTIVO | BB16: RFVW10 | BC16: NISSAN | BD16: QASHQAI J11 2.0 | BE16: 2022 | BF16: 2022
A17: 1563013 | B17: 411 | D17: 4818807 | F17: PHOENIX | G17: JUDICIAL | H17: 366-730 | I17: 366-730 | J17: CASTIGO | K17: COBRANZA | L17: 46180 | N17: 19902496 | O17: 5 | P17: DIEGO FRANCISCO OLGUIN TARIFEÑO | R17: 223.059 | S17: 45663 | W17: TANNER | Y17: 0 | Z17: 0 | AC17: 794218 | AH17: CASTIGO | AI17: 988691761 | AL17: DIEGOOLGUIN01@GMAIL.COM | AO17: SAN ALFONSO 741 | AQ17: REGION METROPOLITANA | AR17: C-19061-2024 | AS17: 1º Juzgado Civil de Santiago | AT17: GIRO CHEQUE | AU17: MANTIENE | AZ17: SI | BA17: ACTIVO | BB17: RKBZ50 | BC17: JAC | BD17: JS2 HATCHBACK 1.5 | BE17: 2022 | BF17: 2022
A18: 1571122 | B18: 258 | D18: 5920000 | F18: PHOENIX | G18: JUDICIAL | H18: 0-365 | I18: 0-365 | J18: CASTIGO | K18: COBRANZA | L18: 46180 | N18: 11641745 | O18: 6 | P18: ANA PAULA GUAJARDO CORDOVA | R18: 275.628 | S18: 45668 | W18: TANNER | Y18: 0 | Z18: 0 | AC18: 676430 | AE18: PLAN DE PAGO | AF18: PHOENIX | AH18: CASTIGO | AI18: 959863045 | AL18: ANA.GUA.COR29@GMAIL.COM | AO18: PASAJE DANCING 5875 | AQ18: REGION METROPOLITANA | AR18: C-3908-2025 | AS18: 26º Juzgado Civil de Santiago | AT18: INGRESADO | AU18: MANTIENE | AZ18: NO | BA18: ACTIVO | BB18: RGZP22 | BC18: CHANGAN | BD18: CS55 ELITE 1.5 AUT | BE18: 2022 | BF18: 2022
A19: 1579447 | B19: 258 | D19: 3774859 | F19: PHOENIX | G19: JUDICIAL | H19: 0-365 | I19: 0-365 | J19: CASTIGO | K19: COBRANZA | L19: 46180 | N19: 18563424 | O19: 8 | P19: ALBERTO FERNANDO MANUEL ALVAREZ VICENCIO | R19: 218.859 | S19: 45668 | W19: TANNER | X19: DACIÓN | Y19: 0 | Z19: 0 | AC19: 3774859 | AH19: CASTIGO | AI19: 962903608 | AL19: lhise.alisdy5@gmail.com | AO19: LAS COIMAS SECTOR LA CANCHA N 4 | AQ19: V REGION | AR19: C-3899-2025 | AS19: 2º Juzgado Civil de Santiago | AT19: EMBARGADO | AU19: MANTIENE | AZ19: SI | BA19: ACTIVO | BB19: RJRF92 | BC19: CHANGAN | BD19: NEW CS 15 LUXURY MT | BE19: 2022 | BF19: 2022
A20: 1585963 | B20: 381 | D20: 6878855 | F20: PHOENIX | G20: JUDICIAL | H20: 366-730 | I20: 366-730 | J20: CASTIGO | K20: COBRANZA | L20: 46180 | N20: 18051143 | O20: 1 | P20: ANGELA ALEJANDRA REBECO PEREZ | R20: 209.574 | S20: 45664 | W20: TANNER | X20: DACIÓN | Y20: 0 | Z20: 0 | AC20: 6878855 | AH20: CASTIGO | AI20: 971792389 | AL20: ANGELAREBECOF@GMAIL.COM | AO20: PASAJE ANTOFAGASTA 2161 | AQ20: REGION METROPOLITANA | AR20: C-20323-2024 | AS20: 26º Juzgado Civil de Santiago | AT20: EMBARGADO | AU20: MANTIENE | AZ20: SI | BA20: ACTIVO | BB20: RHJR26 | BC20: JAC | BD20: JS4 LUXURY HB 1.5 | BE20: 2022 | BF20: 2022
A21: 1603752 | B21: 228 | D21: 3882712 | F21: PHOENIX | G21: JUDICIAL | H21: 0-365 | I21: 0-365 | J21: CASTIGO | K21: COBRANZA | L21: 46180 | N21: 26445123 | O21: K | P21: EDDY SIMON . 0 | R21: 206.712 | S21: 45669 | W21: TANNER | X21: DACIÓN | Y21: 0 | Z21: 0 | AC21: 3882712 | AH21: CASTIGO | AI21: 985379739 | AL21: EDDYSIMON413@GMAIL.COM | AO21: LOS INGLESES 166 | AQ21: REGION METROPOLITANA | AR21: C-5510-2025 | AS21: 17º Juzgado Civil de Santiago | AT21: EMBARGADO | AU21: MANTIENE | AZ21: SI | BA21: ACTIVO | BB21: RLCK51 | BC21: JAC | BD21: JS2 HATCHBACK 1.5 | BE21: 2022 | BF21: 2022
A22: 1609974 | B22: 197 | D22: 3596000 | F22: PHOENIX | G22: JUDICIAL | H22: 0-365 | I22: 0-365 | J22: CASTIGO | K22: COBRANZA | L22: 46180 | N22: 26454470 | O22: K | P22: JORGE ANTONIO SERRANO HERNANDEZ | R22: 182.095 | S22: 46023 | W22: TANNER | X22: DACIÓN | Y22: 0 | Z22: 0 | AC22: 3596000 | AH22: CASTIGO | AI22: 933189626 | AL22: JORGESE1806@GMAIL.COM | AO22: BALMACEDA 749 | AQ22: V REGION | AR22: C-6726-2025 | AS22: 19º Juzgado Civil de Santiago | AT22: INGRESADO | AU22: MANTIENE | AZ22: NO | BA22: ACTIVO | BB22: RJTL81 | BC22: HYUNDAI | BD22: VERNA CB 1.4 | BE22: 2022 | BF22: 2022
A23: 1638465 | B23: 411 | D23: 3871396 | F23: PHOENIX | G23: JUDICIAL | H23: 366-730 | I23: 366-730 | J23: CASTIGO | K23: COBRANZA | L23: 46180 | N23: 27070326 | O23: 7 | P23: LIBIA ROSA VERA TUBIÑEZ | R23: 198.55 | S23: 45663 | W23: TANNER | Y23: 0 | Z23: 0 | AC23: 1254198 | AE23: PLAN DE PAGO | AF23: PHOENIX | AH23: CASTIGO | AI23: 962588898 | AL23: LIBIA.VERA1@GMAIL.COM | AO23: ALCALDE MANUEL HUICHIPOCO 422 | AQ23: REGION METROPOLITANA | AR23: C-19071-2024 | AS23: 3º Juzgado Civil de Santiago | AT23: INGRESADO | AU23: SUSPENDIDO | AZ23: NO | BA23: SUSPENDIDO | BB23: RKHK18 | BC23: SUZUKI | BD23: S PRESSO HB 1.0 | BE23: 2022 | BF23: 2022
A24: 1642440 | B24: 381 | D24: 14121919 | F24: PHOENIX | G24: JUDICIAL | H24: 366-730 | I24: 366-730 | J24: CASTIGO | K24: COBRANZA | L24: 46180 | N24: 16121390 | O24: K | P24: NICOLAS PATRICIO ARRAU SOTO | R24: 460.816 | S24: 45664 | W24: TANNER | X24: DACIÓN | Y24: 0 | Z24: 0 | AC24: 14121919 | AH24: CASTIGO | AI24: 994898377 | AL24: nicoarrau@gmail.com | AO24: MANQUEHUE NORTE 1635 DPTO 104 | AQ24: REGION METROPOLITANA | AR24: C-21660-2024 | AS24: 24º Juzgado Civil de Santiago | AT24: EMBARGADO | AU24: MANTIENE | AZ24: SI | BA24: ACTIVO | BB24: RKXF13 | BC24: MAZDA | BD24: NEW CX 5 R 2.0 AWD 6A | BE24: 2022 | BF24: 2022
A25: 1644932 | B25: 442 | D25: 4868802 | F25: PHOENIX | G25: JUDICIAL | H25: 366-730 | I25: 366-730 | J25: CASTIGO | K25: COBRANZA | L25: 46180 | N25: 16002296 | O25: 5 | P25: MIGUEL ANGEL ACEVEDO ARAVENA | R25: 196.978 | S25: 45662 | W25: TANNER | X25: DACIÓN | Y25: 0 | Z25: 0 | AC25: 2974002 | AE25: PLAN DE PAGO | AF25: PHOENIX | AH25: CASTIGO | AI25: 9987229864 | AL25: MACEVEDOAR@GMAIL.COM | AO25: 30 SUR 19 PONIENTE NÂ°38 | AQ25: VII REGION | AR25: 4º Juzgado Civil de Santiago | AS25: C-16642-2024 | AT25: EMBARGADO | AU25: SUSPENDIDO | AZ25: SI | BA25: SUSPENDIDO | BB25: RJSW95 | BC25: CHANGAN | BD25: ALSVIN LUXURY MT | BE25: 2022 | BF25: 2022
A26: 1645952 | B26: 1 | D26: 9019928 | F26: PHOENIX | G26: JUDICIAL | H26: 0-365 | I26: 0-365 | J26: CASTIGO | K26: COBRANZA | L26: 46180 | M26: E | N26: 15189992 | O26: 7 | P26: ERIK MARCELO ABURTO MORAGA | R26: 381.241 | S26: 46028 | W26: TANNER | Y26: 0 | Z26: 0 | AC26: 9019928 | AH26: CASTIGO | AI26: 977573123 | AL26: ERIK.SERVICIOSCAMIONGRUA@GMAIL.COM | AO26: AVENIDA FEDERICO SCHWAGER 2835 | AQ26: VIII REGION | AR26: C-4685-2025 | AS26: 24º Juzgado Civil de Santiago | AT26: INGRESADO | AU26: MANTIENE | AZ26: NO | BA26: ACTIVO | BB26: RSWR55 | BC26: GREAT WALL | BD26: POER 4X4 2.0 | BE26: 2022 | BF26: 2022
A27: 1670767 | B27: 166 | D27: 6378399 | F27: PHOENIX | G27: JUDICIAL | H27: 0-365 | I27: 0-365 | J27: CASTIGO | K27: COBRANZA | L27: 46180 | N27: 17484899 | O27: 8 | P27: ANGÉLICA ESTER NARVÁEZ CASTRO | R27: 337.109 | S27: 46024 | W27: CREDINISSAN | Y27: 0 | Z27: 0 | AC27: 2385892 | AH27: CASTIGO | AI27: 945865081 | AL27: ANGELICA.NAR.CAS@GMAIL.COM | AO27: VIOLETA PARRA 1954 DPTO. I 212 | AP27: LA PINTANA | AQ27: REGION METROPOLITANA | AR27: C-8323-2025 | AS27: 28º Juzgado Civil de Santiago | AT27: GIRO CHEQUE | AU27: MANTIENE | AZ27: SI | BA27: ACTIVO | BB27: RRJV47 | BC27: NISSAN | BD27: SENTRA MT 2.0 | BE27: 2022 | BF27: 2022
A28: 1700218 | B28: 166 | D28: 6879999 | F28: PHOENIX | G28: JUDICIAL | H28: 0-365 | I28: 0-365 | J28: CASTIGO | K28: COBRANZA | L28: 46180 | N28: 12218160 | O28: K | P28: JUAN ALEX OLIVARES ALANO | R28: 362.214 | S28: 46024 | W28: CREDINISSAN | X28: DACIÓN | Y28: 0 | Z28: 0 | AC28: 5108469 | AE28: PLAN DE PAGO | AF28: PHOENIX | AH28: CASTIGO | AI28: 957500333 | AL28: OLIVARESALANO@GMAIL.COM | AO28: FERNANDO DE AGUIRRE 850 POBLACIÓN CARTAVIO | AP28: COPIAPO | AQ28: III REGION | AR28: 25º Juzgado Civil de Santiago | AS28: C-15693-2024 | AT28: INGRESADO | AU28: MANTIENE | AZ28: NO | BA28: ACTIVO | BB28: RKRY65 | BC28: NISSAN | BD28: KICKS CVT 1.6 AUT | BE28: 2022 | BF28: 2022
A29: 1721051 | B29: 350 | D29: 9984524 | F29: PHOENIX | G29: JUDICIAL | H29: 0-365 | I29: 0-365 | J29: CASTIGO | K29: COBRANZA | L29: 46180 | N29: 16409957 | O29: 1 | P29: ROBERTO CARLOS NEER CERDA | R29: 313.969 | S29: 45665 | W29: TANNER | X29: DACIÓN | Y29: 0 | Z29: 0 | AC29: 9984524 | AH29: CASTIGO | AI29: 93241652 | AL29: rc.neer@gmail.com | AO29: PASAJE LOS ARAUCANOS 01351 | AP29: PUENTE ALTO | AQ29: REGION METROPOLITANA | AR29: C-22132-2024 | AS29: 25º Juzgado Civil de Santiago | AT29: EMBARGADO | AU29: MANTIENE | AZ29: SI | BA29: ACTIVO | BB29: RRRF12 | BC29: JAC | BD29: T8 XE ADVANCE 2.0 | BE29: 2022 | BF29: 2022
A30: 1729656 | B30: 411 | D30: 4994124 | F30: PHOENIX | G30: JUDICIAL | H30: 366-730 | I30: 366-730 | J30: CASTIGO | K30: COBRANZA | L30: 46180 | N30: 13621515 | O30: 9 | P30: VERÓNICA DE LAS MERCEDES SAN MARTÍN LAGOS | R30: 256.836 | S30: 45663 | W30: TANNER | X30: DACIÓN | Y30: 0 | Z30: 0 | AC30: 4994124 | AH30: CASTIGO | AI30: 991355756 | AL30: VERONICASANMARTINLAGOS@GMAIL.COM | AO30: CONDE DEL MAULE 668 | AP30: CHILLAN VIEJO | AQ30: XVI REGION | AR30: C-19071-2024 | AS30: 29º Juzgado Civil de Santiago | AT30: INGRESADO | AU30: MANTIENE | AZ30: NO | BA30: ACTIVO | BB30: HYCV69 | BC30: HYUNDAI | BD30: ACCENT RB 1.4 | BE30: 2016 | BF30: 2016
A31: 1735638 | B31: 197 | D31: 4850702 | F31: PHOENIX | G31: JUDICIAL | H31: 0-365 | I31: 0-365 | J31: CASTIGO | K31: COBRANZA | L31: 46180 | N31: 15656935 | O31: 6 | P31: RAMÓN ALONSO VÁSQUEZ BUSTOS | R31: 347.26 | S31: 46023 | W31: TANNER | X31: DACIÓN | Y31: 0 | Z31: 0 | AC31: 4850702 | AE31: PLAN DE PAGO | AF31: PHOENIX | AH31: CASTIGO | AI31: 9930097642 | AL31: Herramientasramon1@gmail.com | AO31: LOS CULTIVADORES 0563 | AP31: TEMUCO | AQ31: IX REGION | AR31: C-19068-2024 | AS31: 21º Juzgado Civil de Santiago | AT31: INGRESADO | AU31: MANTIENE | AZ31: NO | BA31: ACTIVO | BB31: GWYT99 | BC31: FORD | BD31: ESCAPE 2.5 AUT | BE31: 2015 | BF31: 2015
A32: 1746743 | B32: 472 | D32: 4502714 | F32: PHOENIX | G32: JUDICIAL | H32: 366-730 | I32: 366-730 | J32: CASTIGO | K32: COBRANZA | L32: 46180 | N32: 26896838 | O32: 5 | P32: GERMAN ANTONIO GONZALEZ SANCHEZ | R32: 197.007 | S32: 45661 | W32: TANNER | X32: DACIÓN | Y32: 0 | Z32: 0 | AC32: 4502714 | AH32: CASTIGO | AI32: 9935804367 | AL32: iramandarcia@gmail.com | AO32: AV. ESCUELA AGRICOLA 1710 DEPTO 1605 | AP32: MACUL | AQ32: REGION METROPOLITANA | AR32: 19º Juzgado Civil de Santiago | AS32: C-15713-2024 | AT32: EMBARGADO | AU32: MANTIENE | AZ32: SI | BA32: ACTIVO | BB32: RRKJ66 | BC32: SUZUKI | BD32: ALTO 800 GLX AC | BE32: 2022 | BF32: 2022
A33: 1749842 | B33: 166 | D33: 4940063 | F33: PHOENIX | G33: JUDICIAL | H33: 0-365 | I33: 0-365 | J33: CASTIGO | K33: COBRANZA | L33: 46180 | N33: 16823710 | O33: 3 | P33: REINALDO DAVID ALCAMÁN HUENULAF | R33: 380.198 | S33: 46024 | W33: CREDINISSAN | X33: DACIÓN | Y33: 0 | Z33: 0 | AC33: 4940063 | AH33: CASTIGO | AI33: 981496520 | AL33: reypausa@gmail.com | AO33: PATRICIO LINCH 1040 DEPARTAMENTO 105 | AP33: TEMUCO | AQ33: IX REGION | AR33: C-8327-2025 | AS33: 16º Juzgado Civil de Santiago | AT33: EMBARGADO | AU33: MANTIENE | AZ33: SI | BA33: ACTIVO | BB33: RRYZ76 | BC33: NISSAN | BD33: SENTRA MT 2.0 | BE33: 2022 | BF33: 2022
A34: 1752476 | B34: 411 | D34: 6198242 | F34: PHOENIX | G34: JUDICIAL | H34: 366-730 | I34: 366-730 | J34: CASTIGO | K34: COBRANZA | L34: 46180 | N34: 18957719 | O34: 2 | P34: PEDRO GERMAN ESPINOZA MUÑOZ | R34: 190.562 | S34: 45663 | W34: TANNER | X34: DACIÓN | Y34: 0 | Z34: 0 | AC34: 6198242 | AH34: CASTIGO | AI34: 978819922 | AL34: pedro_name@hotmail.com | AO34: CALLE 2 CASA 749 BOCA SUR | AP34: SAN PEDRO DE LA PAZ | AQ34: VIII REGION | AR34: C-19074-2024 | AS34: 10º Juzgado Civil de Santiago | AT34: EMBARGADO | AU34: MANTIENE | AZ34: SI | BA34: ACTIVO | BB34: RTRZ90 | BC34: CHANGAN | BD34: ALSVIN 1.4 | BE34: 2022 | BF34: 2022
A35: 1763682 | B35: 228 | D35: 6001534 | F35: PHOENIX | G35: JUDICIAL | H35: 0-365 | I35: 0-365 | J35: CASTIGO | K35: COBRANZA | L35: 46180 | N35: 17941976 | O35: 9 | P35: HANS ALEXANDER BÓRQUEZ CHACANA | R35: 401.782 | S35: 45669 | W35: TANNER | X35: DACIÓN | Y35: 0 | Z35: 0 | AC35: 6001534 | AH35: CASTIGO | AI35: 965291697 | AL35: THRON.7@LIVE.COM | AO35: AVENIDA CARLOS VALDOVINOS 1055 DEPTO. 187 | AP35: SAN MIGUEL | AQ35: REGION METROPOLITANA | AR35: C-5508-2025 | AS35: 3º Juzgado Civil de Santiago | AT35: EMBARGADO | AU35: MANTIENE | AZ35: SI | BA35: ACTIVO | BB35: JCRV58 | BC35: MERCEDES BENZ | BD35: A200 D | BE35: 2016 | BF35: 2016
A36: 1769156 | B36: 472 | D36: 7241243 | F36: PHOENIX | G36: JUDICIAL | H36: 366-730 | I36: 366-730 | J36: CASTIGO | K36: COBRANZA | L36: 46180 | N36: 7710884 | O36: K | P36: MARÍA ANGÉLICA VERGARA SILVA | R36: 330.069 | S36: 45661 | W36: TANNER | X36: DACIÓN | Y36: 0 | Z36: 0 | AC36: 2765723 | AE36: PLAN DE PAGO | AF36: PHOENIX | AH36: CASTIGO | AI36: 944758247 | AL36: janomarver1974@gmail.com | AO36: HORNILLAS 01651 | AP36: PUNTA ARENAS | AQ36: XII REGION | AR36: 9º Juzgado Civil de Santiago | AS36: C-16645-2024 | AT36: INGRESADO | AU36: SUSPENDIDO | AZ36: NO | BA36: SUSPENDIDO | BB36: RPYY87 | BC36: HYUNDAI | BD36: SANTA FE 2.0 AUT | BE36: 2014 | BF36: 2014
A37: 1777539 | B37: 166 | D37: 9123246 | F37: PHOENIX | G37: JUDICIAL | H37: 0-365 | I37: 0-365 | J37: CASTIGO | K37: COBRANZA | L37: 46180 | N37: 12002438 | O37: 8 | P37: LUIS FRANCISCO JAVIER ESCOBAR MUÑOZ | R37: 375.18 | S37: 46024 | W37: TANNER | X37: DACIÓN | Y37: 0 | Z37: 0 | AC37: 9123246 | AH37: CASTIGO | AI37: 56995083890 | AL37: LFJAVIER69@HOTMAIL.COM | AO37: ANDES 1506 | AQ37: III REGION | AR37: C-8325-2025 | AS37: 4º JUZGADO CIVIL DE SANTIAGO | AT37: INGRESADO | AU37: MANTIENE | AZ37: NO | BA37: ACTIVO | BB37: KSRX96 | BC37: JEEP | BD37: RENEGADE SPORT 1.8 | BE37: 2019 | BF37: 2019
A38: 1782538 | B38: 350 | D38: 5247436 | F38: PHOENIX | G38: JUDICIAL | H38: 0-365 | I38: 0-365 | J38: CASTIGO | K38: COBRANZA | L38: 46180 | N38: 16174268 | O38: 6 | P38: JACQUELINE ANDREA GONZÁLEZ CALDERON | R38: 258.197 | S38: 45665 | W38: TANNER | X38: DACIÓN | Y38: 0 | Z38: 0 | AC38: 5247436 | AH38: CASTIGO | AI38: 953673166 | AL38: JAGONZALEZC@MALLCENTER.CL | AO38: AFLUENTE 1932 | AQ38: REGION METROPOLITANA | AR38: C-22302-2024 | AS38: 22º Juzgado Civil de Santiago | AT38: EMBARGADO | AU38: MANTIENE | AZ38: SI | BA38: ACTIVO | BB38: LPFT73 | BC38: KIA MOTORS | BD38: MORNING EX 1.2 | BE38: 2019 | BF38: 2019
A39: 1783098 | B39: 411 | D39: 5978132 | F39: PHOENIX | G39: JUDICIAL | H39: 366-730 | I39: 366-730 | J39: CASTIGO | K39: COBRANZA | L39: 46180 | N39: 15642246 | O39: 0 | P39: EVELYN ALEJANDRA AHUMADA PADILLA | R39: 272.819 | S39: 45663 | W39: TANNER | Y39: 0 | Z39: 0 | AC39: 2471892 | AH39: CASTIGO | AI39: 958355504 | AL39: e.ahumadapadilla@gmail.com | AO39: romerillo 3735 | AP39: PUENTE ALTO | AQ39: REGION METROPOLITANA | AR39: 2º Juzgado Civil de Santiago | AS39: C-16646-2024 | AT39: GIRO CHEQUE | AU39: MANTIENE | AZ39: SI | BA39: ACTIVO | BB39: JJTF54 | BC39: NISSAN | BD39: VERSA SENSE 1.6 AUT | BE39: 2017 | BF39: 2017
A40: 1791083 | B40: 503 | D40: 7569433 | F40: PHOENIX | G40: JUDICIAL | H40: 366-730 | I40: 366-730 | J40: CASTIGO | K40: COBRANZA | L40: 46180 | N40: 15236244 | O40: 7 | P40: RUBÉN ANER CARILAO BARRA | R40: 322.355 | S40: 45660 | W40: TANNER | X40: DACIÓN | Y40: 0 | Z40: 0 | AC40: 5474529 | AE40: PLAN DE PAGO | AF40: PHOENIX | AH40: CASTIGO | AI40: 968259519 | AL40: rubenaner@gmail.com | AO40: La Huasca 10834 | AP40: LA FLORIDA | AQ40: REGION METROPOLITANA | AR40: 16º Juzgado Civil de Santiago | AS40: C-16644-2024 | AT40: EMBARGADO | AU40: SUSPENDIDO | AW40: SUSPENDER | AX40: PLAN DE PAGO | AY40: 13-07-2026 | AZ40: SI | BA40: SUSPENDIDO | BB40: RTFH40 | BC40: KYC | BD40: X5 DCAB 1.5 | BE40: 2022 | BF40: 2022
...

Sheet PLAN-PUT
A1: ID_CREDITO | B1: DIAS_MORA | C1: CUOTAS_MOROSAS_ACTUAL | D1: SALDO_INSOLUTO_INI | E1: PRIORIDAD_GESTION | F1: GESTOR | G1: TIPO_COBRANZA | H1: TRAMO_INI | I1: TRAMO_ACT | J1: TIPO_CARTERA | K1: TIPO_GESTION | L1: FECHA_ASIGNACION | M1: SEGMENTO_CLIENTE | N1: RUT | O1: DV | P1: RAZON_SOCIAL | Q1: PERSONA_NATURAL | R1: VALOR_CUOTA | S1: FECHA_PROX_VCTO | T1: CUOTAS_PAGADAS_ACTUAL | U1: CUOTAS_PAGADAS_INI | V1: PLAZO | W1: CANAL_VENTA | X1: CAMPANAS | Y1: INT_MORA_TOTAL | Z1: GC_TOTAL | AA1: ESTADO_PAT_PAC | AB1: FECHA_FIRMA_PAGARE | AC1: MONTO_ADEUDADO | AD1: TASA_INTERES_CRED | AE1: CONVENIO_CASTIGO | AF1: GESTOR_PLAN_PAGO | AG1: MARCA_CLIENTE | AH1: ESTADO_COBRANZA | AI1: TELEFONO_1 | AJ1: TELEFONO_2 | AK1: TELEFONO_3 | AL1: EMAIL_1 | AM1: EMAIL_2 | AN1: EMAIL_3 | AO1: DIRECCION | AP1: COMUNA | AQ1: REGION | AR1: ROL | AS1: TRIBUNAL | AT1: ESTADO_JUDICIAL | AU1: TIPO_JUDICIAL | AV1: DUAL | AW1: SUSP_ESTADO_JUDICIAL | AX1: SUSP_MOTIVO | AY1: SUSP_FECHA | AZ1: NOTIFICADO | BA1: ESTADO_JUICIO | BB1: VEHICULO_1_PATENTE | BC1: VEHICULO_1_MARCA | BD1: VEHICULO_1_MODELO | BE1: VEHICULO_1_ANIO
A2: 1383598 | B2: 279 | D2: 3596000 | F2: PHOENIX | G2: JUDICIAL | H2: 0-365 | I2: 0-365 | J2: CASTIGO | K2: COBRANZA | L2: 46118 | N2: 15667044 | O2: 8 | P2: SEBASTIÁN ESTEBAN VILLAGRA CISTERNAS | R2: 225287 | S2: 45839 | W2: TANNER | Y2: 0 | Z2: 0 | AC2: 1548000 | AE2: PLAN DE PAGO | AF2: PHOENIX | AH2: CASTIGO | AI2: 933429038 | AL2: svillagra1984@gmail.com | AO2: SAN PABLO 4025, DEPTO 1814 | AP2: QUINTA NORMAL | AQ2: REGION METROPOLITANA | AR2: C-19083-2024 | AS2: 18º Juzgado Civil de Santiago | AT2: INGRESADO | AU2: SUSPENDIDO | AZ2: NO | BA2: CERRADO | BB2: PYSF60 | BC2: VOLKSWAGEN | BD2: NUEVO VOYAGE HIGHLINE 1.6 | BE2: 2021
A3: 1397586 | B3: 248 | D3: 5796000 | F3: PHOENIX | G3: JUDICIAL | H3: 0-365 | I3: 0-365 | J3: CASTIGO | K3: COBRANZA | L3: 46118 | N3: 16482560 | O3: 4 | P3: ITALO ADOLFO MUÑOZ PAREDES MUÑOZ PAREDES | R3: 266289 | S3: 45870 | W3: TANNER | Y3: 0 | Z3: 0 | AC3: 451088 | AE3: PUT EN CUOTAS | AF3: PHOENIX | AH3: CASTIGO | AI3: 971949267 | AL3: ITALOMPAREDES1987@ICLOUD.COM | AO3: PASAJE CASTELLÓN 1993 ALTO OSORNO | AP3: OSORNO | AQ3: X REGION | AR3: C-21976-2024 | AS3: 24º Juzgado Civil de Santiago | AT3: GIRO CHEQUE | AU3: MANTIENE | AZ3: SI | BA3: CERRADO | BB3: PZTC12 | BC3: RENAULT | BD3: OROCH OTTO 2.0 | BE3: 2021
A4: 1524638 | B4: 126 | D4: 3499999 | F4: PHOENIX | G4: JUDICIAL | H4: 0-365 | I4: 0-365 | J4: CASTIGO | K4: COBRANZA | L4: 46118 | N4: 12712897 | O4: 9 | P4: DENISE DE LOURDES ARTEAGA GÓMEZ | R4: 358441 | S4: 45992 | W4: CREDINISSAN | Y4: 0 | Z4: 0 | AC4: 2624999 | AE4: PUT EN CUOTAS | AF4: PHOENIX | AH4: CASTIGO | AI4: 998656256 | AL4: DENISEARTEAGA@GMAIL.COM | AO4: SANTA INES 1060 | AP4: PUERTO MONTT | AQ4: X REGION | AR4: C-19078-2024 | AS4: 26º Juzgado Civil de Santiago | AT4: INGRESADO | AU4: REACTIVA | AZ4: NO | BA4: ACTIVO | BB4: RHPP76 | BC4: NISSAN | BD4: X TRAIL CVT 2.5 AT | BE4: 2022
A5: 1571122 | B5: 156 | D5: 5920000 | F5: PHOENIX | G5: JUDICIAL | H5: 0-365 | I5: 0-365 | J5: CASTIGO | K5: COBRANZA | L5: 46118 | N5: 11641745 | O5: 6 | P5: ANA PAULA GUAJARDO CORDOVA | R5: 275628 | S5: 45962 | W5: TANNER | Y5: 0 | Z5: 0 | AC5: 676430 | AE5: PLAN DE PAGO | AF5: PHOENIX | AH5: CASTIGO | AI5: 959863045 | AL5: ANA.GUA.COR29@GMAIL.COM | AO5: PASAJE DANCING 5875 | AQ5: REGION METROPOLITANA | AR5: C-3908-2025 | AS5: 26º Juzgado Civil de Santiago | AT5: INGRESADO | AU5: MANTIENE | AZ5: NO | BA5: ACTIVO | BB5: RGZP22 | BC5: CHANGAN | BD5: CS55 ELITE 1.5 AUT | BE5: 2022
A6: 1638465 | B6: 309 | D6: 3871396 | F6: PHOENIX | G6: JUDICIAL | H6: 0-365 | I6: 0-365 | J6: CASTIGO | K6: COBRANZA | L6: 46118 | N6: 27070326 | O6: 7 | P6: LIBIA ROSA VERA TUBIÑEZ | R6: 198550 | S6: 45809 | W6: TANNER | Y6: 0 | Z6: 0 | AC6: 1942286 | AE6: PLAN DE PAGO | AF6: PHOENIX | AH6: CASTIGO | AI6: 962588898 | AL6: LIBIA.VERA1@GMAIL.COM | AO6: ALCALDE MANUEL HUICHIPOCO 422 | AQ6: REGION METROPOLITANA | AR6: C-19071-2024 | AS6: 3º Juzgado Civil de Santiago | AT6: INGRESADO | AU6: SUSPENDIDO | AZ6: NO | BA6: SUSPENDIDO | BB6: RKHK18 | BC6: SUZUKI | BD6: S PRESSO HB 1.0 | BE6: 2022
A7: 1644932 | B7: 340 | D7: 4868802 | F7: PHOENIX | G7: JUDICIAL | H7: 0-365 | I7: 0-365 | J7: CASTIGO | K7: COBRANZA | L7: 46118 | N7: 16002296 | O7: 5 | P7: MIGUEL ANGEL ACEVEDO ARAVENA | R7: 196978 | S7: 45778 | W7: TANNER | Y7: 0 | Z7: 0 | AC7: 3420102 | AE7: PLAN DE PAGO | AF7: PHOENIX | AH7: CASTIGO | AI7: 9987229864 | AL7: MACEVEDOAR@GMAIL.COM | AO7: 30 SUR 19 PONIENTE NÂ°38 | AQ7: VII REGION | AR7: 4º Juzgado Civil de Santiago | AS7: C-16642-2024 | AT7: EMBARGADO | AU7: SUSPENDIDO | AZ7: SI | BA7: SUSPENDIDO | BB7: RJSW95 | BC7: CHANGAN | BD7: ALSVIN LUXURY MT | BE7: 2022
A8: 1700218 | B8: 64 | D8: 6879999 | F8: PHOENIX | G8: JUDICIAL | H8: 0-365 | I8: 0-365 | J8: CASTIGO | K8: COBRANZA | L8: 46118 | M8: E | N8: 12218160 | O8: K | P8: JUAN ALEX OLIVARES ALANO | R8: 362214 | S8: 46054 | W8: CREDINISSAN | Y8: 0 | Z8: 0 | AC8: 6517785 | AE8: PLAN DE PAGO | AF8: PHOENIX | AH8: CASTIGO | AI8: 957500333 | AL8: OLIVARESALANO@GMAIL.COM | AO8: FERNANDO DE AGUIRRE 850 POBLACIÓN CARTAVIO | AP8: COPIAPO | AQ8: III REGION | AR8: 25º Juzgado Civil de Santiago | AS8: C-15693-2024 | AT8: INGRESADO | AU8: MANTIENE | AZ8: NO | BA8: ACTIVO | BB8: RKRY65 | BC8: NISSAN | BD8: KICKS CVT 1.6 AUT | BE8: 2022
A9: 1769156 | B9: 370 | D9: 7241243 | F9: PHOENIX | G9: JUDICIAL | H9: 366-730 | I9: 366-730 | J9: CASTIGO | K9: COBRANZA | L9: 46118 | N9: 7710884 | O9: K | P9: MARÍA ANGÉLICA VERGARA SILVA | R9: 330069 | S9: 45748 | W9: TANNER | Y9: 0 | Z9: 0 | AC9: 3160827 | AE9: PLAN DE PAGO | AF9: PHOENIX | AH9: CASTIGO | AI9: 944758247 | AL9: janomarver1974@gmail.com | AO9: HORNILLAS 01651 | AP9: PUNTA ARENAS | AQ9: XII REGION | AR9: 9º Juzgado Civil de Santiago | AS9: C-16645-2024 | AT9: INGRESADO | AU9: SUSPENDIDO | AZ9: NO | BA9: SUSPENDIDO | BB9: RPYY87 | BC9: HYUNDAI | BD9: SANTA FE 2.0 AUT | BE9: 2014
A10: 1791083 | B10: 401 | D10: 7569433 | F10: PHOENIX | G10: JUDICIAL | H10: 366-730 | I10: 366-730 | J10: CASTIGO | K10: COBRANZA | L10: 46118 | N10: 15236244 | O10: 7 | P10: RUBÉN ANER CARILAO BARRA | R10: 322355 | S10: 45717 | W10: TANNER | Y10: 0 | Z10: 0 | AC10: 6295707 | AE10: PLAN DE PAGO | AF10: PHOENIX | AH10: CASTIGO | AI10: 968259519 | AL10: rubenaner@gmail.com | AO10: La Huasca 10834 | AP10: LA FLORIDA | AQ10: REGION METROPOLITANA | AR10: 16º Juzgado Civil de Santiago | AS10: C-16644-2024 | AT10: EMBARGADO | AU10: SUSPENDIDO | AZ10: SI | BA10: SUSPENDIDO | BB10: RTFH40 | BC10: KYC | BD10: X5 DCAB 1.5 | BE10: 2022
A11: 1891178 | B11: 156 | D11: 6382600 | F11: PHOENIX | G11: JUDICIAL | H11: 0-365 | I11: 0-365 | J11: CASTIGO | K11: COBRANZA | L11: 46118 | N11: 26313552 | O11: 0 | P11: WILLIAMS JOSE CHACIN MARTINEZ | R11: 301100 | S11: 45962 | W11: TANNER | Y11: 0 | Z11: 0 | AC11: 6382600 | AE11: PLAN DE PAGO | AF11: PHOENIX | AH11: CASTIGO | AI11: 979125999 | AL11: LUISANNAISABELL@GMAIL.COM | AO11: PDTE SANTA MARIA 289 | AQ11: REGION METROPOLITANA | AR11: C-5521-2025 | AS11: 23º Juzgado Civil de Santiago | AT11: EMBARGADO | AU11: MANTIENE | AZ11: SI | BA11: ACTIVO | BB11: RWZK66 | BC11: SUZUKI | BD11: BALENO GLS HB 1.4 | BE11: 2022
A12: 1923591 | B12: 248 | D12: 11082144 | F12: PHOENIX | G12: JUDICIAL | H12: 0-365 | I12: 0-365 | J12: CASTIGO | K12: COBRANZA | L12: 46118 | N12: 16647012 | O12: 9 | P12: FABRICIO ALEJANDRO VALENZUELA LEIVA | R12: 375735 | S12: 45870 | W12: TANNER | Y12: 0 | Z12: 0 | AC12: 8056774 | AE12: PLAN DE PAGO | AF12: PHOENIX | AH12: CASTIGO | AI12: 977915708 | AL12: fabricio.valenzuela.leiva@gmail.com | AO12: EL LLANO 9 | AP12: SAN BERNARDO | AQ12: REGION METROPOLITANA | AR12: C-22141-2024 | AS12: 29º Juzgado Civil de Santiago | AT12: INGRESADO | AU12: SUSPENDIDO | AZ12: NO | BA12: SUSPENDIDO | BB12: RXTT99 | BC12: JAC | BD12: T8 PRO DIESEL ADVANCE 4X4 2.0 | BE12: 2022
A13: 1987553 | B13: 279 | D13: 10554087 | F13: PHOENIX | G13: JUDICIAL | H13: 0-365 | I13: 0-365 | J13: CASTIGO | K13: COBRANZA | L13: 46118 | N13: 15242687 | O13: 9 | P13: GIORGIO GENNARO SARTORI TORRES | R13: 317140 | S13: 45839 | W13: TANNER | Y13: 0 | Z13: 0 | AC13: 7309826 | AE13: PLAN DE PAGO | AF13: PHOENIX | AH13: CASTIGO | AI13: 975171907 | AL13: giorgio.sartori.t@gmail.com | AO13: AVENIDA JARDINES DE RENACA 102 | AP13: VIÑA DEL MAR | AQ13: V REGION | AR13: 20º Juzgado Civil de Santiago | AS13: C-15706-2024 | AT13: INGRESADO | AU13: SUSPENDIDO | AZ13: NO | BA13: SUSPENDIDO | BB13: SBWB47 | BC13: MAZDA | BD13: NEW 3 HB 2.0 | BE13: 2022
A14: 2041907 | B14: 309 | D14: 8500246 | F14: PHOENIX | G14: JUDICIAL | H14: 0-365 | I14: 0-365 | J14: CASTIGO | K14: COBRANZA | L14: 46118 | N14: 12446328 | O14: 9 | P14: CLAUDIA LORENA ROJAS ARRIARÁN | R14: 344179 | S14: 45809 | W14: TANNER | Y14: 0 | Z14: 0 | AC14: 6286246 | AE14: PLAN DE PAGO | AF14: PHOENIX | AH14: CASTIGO | AI14: +56953547488 | AL14: PAULETIGNACIA26@gmail.com | AO14: PASAJE CAPELLAN PABLO VALLIER 2880 | AP14: LA SERENA | AQ14: IV REGION | AR14: C-19064-2024 | AS14: 25º JUZGADO CIVIL DE SANTIAGO | AT14: INGRESADO | AU14: SUSPENDIDO | AZ14: NO | BA14: SUSPENDIDO | BB14: GFCS66 | BC14: HYUNDAI | BD14: PORTER HR CRDI 2.5 | BE14: 2014
A15: 2221834 | B15: 309 | D15: 3892558 | F15: PHOENIX | G15: JUDICIAL | H15: 0-365 | I15: 0-365 | J15: CASTIGO | K15: COBRANZA | L15: 46118 | N15: 26793032 | O15: 5 | P15: CARLOS ALBERTO GIANNOTTY MORENO | R15: 221578 | S15: 45809 | W15: TANNER | Y15: 0 | Z15: 0 | AC15: 3642558 | AE15: PLAN DE PAGO | AF15: PHOENIX | AH15: CASTIGO | AI15: 959766639 | AL15: Carlosagiannotti@gmail.com | AO15: NUEVA LOS LEONES 0253 | AP15: PROVIDENCIA | AQ15: REGION METROPOLITANA | AR15: 24º Juzgado Civil de Santiago | AS15: C-15608-2024 | AT15: INGRESADO | AU15: MANTIENE | AZ15: NO | BA15: ACTIVO | BB15: WHP019 | BC15: YAMAHA | BD15: MT-03A | BE15: 2023
A16: 2316103 | B16: 309 | D16: 8882006 | F16: PHOENIX | G16: JUDICIAL | H16: 0-365 | I16: 0-365 | J16: CASTIGO | K16: COBRANZA | L16: 46118 | N16: 76287256 | O16: 0 | P16: COMERCIALIZADORA ALPES LIMITADA | R16: 234347 | S16: 45809 | W16: TANNER | Y16: 0 | Z16: 0 | AC16: 8882006 | AE16: PUT EN CUOTAS | AF16: PHOENIX | AH16: CASTIGO | AI16: 942283930 | AL16: MPARADA@ALPESLTDA.CL | AO16: NIMES | AR16: C-19082-2024 | AS16: 18º Juzgado Civil de Santiago | AT16: EMBARGADO | AU16: MANTIENE | AZ16: SI | BA16: ACTIVO | BB16: RFXS15 | BC16: CITROEN | BD16: BERLINGO 2 HDI 1.6 | BE16: 2022
A17: 2359330 | B17: 429 | D17: 17079615 | F17: PHOENIX | G17: JUDICIAL | H17: 366-730 | I17: 366-730 | J17: CASTIGO | K17: COBRANZA | L17: 46118 | N17: 14387173 | O17: 8 | P17: SOLEDAD DEL CARMEN ALFARO PINTO | R17: 457241 | S17: 45689 | W17: TANNER | Y17: 0 | Z17: 0 | AC17: 12315615 | AE17: PLAN DE PAGO | AF17: PHOENIX | AH17: CASTIGO | AI17: 971808740 | AL17: soledadalfaro.pinto@gmail.com | AO17: OLEA 3869 CASA E | AP17: ISLA DE MAIPO | AQ17: REGION METROPOLITANA | AR17: 16º Juzgado Civil de Santiago | AS17: C-15702-2024 | AT17: EMBARGADO | AU17: SUSPENDIDO | AZ17: SI | BA17: SUSPENDIDO | BB17: SRFJ82 | BC17: GEELY | BD17: AZKARRA 1.5TD 6AT GL 2WD EXCLUSIVE | BE17: 2023
A18: 2361546 | B18: 187 | D18: 5966279 | F18: PHOENIX | G18: JUDICIAL | H18: 0-365 | I18: 0-365 | J18: CASTIGO | K18: COBRANZA | L18: 46118 | N18: 18845546 | O18: 8 | P18: PAULETTE CRISTINA PEÑA JARA | R18: 234494 | S18: 45931 | W18: TANNER | Y18: 0 | Z18: 0 | AC18: 4966279 | AE18: PLAN DE PAGO | AF18: PHOENIX | AH18: CASTIGO | AI18: 981279138 | AL18: ppena4372@gmail.com | AO18: Calle Salitrera Rica Aventura, El Palomar 542 | AP18: COPIAPO | AQ18: III REGION | AR18: C-22161-2024 | AS18: 7º Juzgado Civil de Santiago | AT18: EMBARGADO | AU18: MANTIENE | AZ18: SI | BA18: ACTIVO | BB18: JDKT88 | BC18: FORD | BD18: ECOSPORT TITANIUM 1.6 | BE18: 2017
A19: 2410360 | B19: 217 | D19: 5047680 | F19: PHOENIX | G19: JUDICIAL | H19: 0-365 | I19: 0-365 | J19: CASTIGO | K19: COBRANZA | L19: 46118 | N19: 13291544 | O19: K | P19: ANDREA DEL PILAR GONZÁLEZ URETA | R19: 274774 | S19: 45901 | W19: TANNER | Y19: 0 | Z19: 0 | AC19: 2960760 | AE19: PLAN DE PAGO | AF19: PHOENIX | AH19: CASTIGO | AI19: 948899401 | AL19: agonzalez1977ureta@gmail.com | AO19: PIELAGO DEL SUR 1866 | AP19: LA FLORIDA | AQ19: REGION METROPOLITANA | AR19: C-685-2025 | AS19: 12º Juzgado Civil de Santiago | AT19: EMBARGADO | AU19: SUSPENDIDO | AZ19: SI | BA19: SUSPENDIDO | BB19: SRSZ86 | BC19: FOTON | BD19: MIDI DOBLE 1.3 | BE19: 2023
A20: 2757617 | B20: 95 | D20: 9115829 | F20: PHOENIX | G20: JUDICIAL | H20: 0-365 | I20: 0-365 | J20: CASTIGO | K20: COBRANZA | L20: 46118 | M20: E | N20: 10908669 | O20: K | P20: OSCAR RICARDO ROMERO GONZÁLEZ | R20: 309130 | S20: 46023 | W20: TANNER | Y20: 0 | Z20: 0 | AC20: 9115829 | AE20: PUT EN CUOTAS | AF20: PHOENIX | AH20: CASTIGO | AI20: 964496387 | AL20: ROMINAROMEROCARRASCO@GMAIL.COM | AO20: LAS BANDURRIAS 10915 VILLA COLOMBIA | AP20: LA PINTANA | AQ20: REGION METROPOLITANA | AR20: C-6724-2025 | AS20: 18º Juzgado Civil de Santiago | AT20: EMBARGADO | AU20: MANTIENE | AZ20: SI | BA20: ACTIVO | BB20: TDZV42 | BC20: DFM | BD20: T5 | BE20: 2024
A21: 2762910 | B21: 340 | D21: 15253118 | F21: PHOENIX | G21: JUDICIAL | H21: 0-365 | I21: 0-365 | J21: CASTIGO | K21: COBRANZA | L21: 46118 | N21: 9369669 | O21: 7 | P21: CARLOS ORLANDO PLAZA COLMAN | R21: 316420 | S21: 45778 | W21: TANNER | Y21: 0 | Z21: 0 | AC21: 15253118 | AE21: PLAN DE PAGO | AF21: PHOENIX | AH21: CASTIGO | AI21: 992941506 | AL21: CARLOSPIEZACOLMAN@GMAIL.COM | AO21: MANUEL MONTT | AP21: TIERRA AMARILLA | AQ21: III REGION | AR21: 11º Juzgado Civil de Santiago | AS21: C-15702-2024 | AT21: EMBARGADO | AU21: MANTIENE | AZ21: SI | BA21: ACTIVO | BB21: SDJY64 | BC21: HAVAL | BD21: JOLION ACTIVE 1.5 | BE21: 2022
A22: 3115557 | B22: 95 | D22: 10316441 | F22: PHOENIX | G22: JUDICIAL | H22: 0-365 | I22: 0-365 | J22: CASTIGO | K22: COBRANZA | L22: 46118 | M22: E | N22: 18488596 | O22: 4 | P22: ELENA ROMANE VIDAL GOMEZ | R22: 280540 | S22: 46023 | W22: TANNER | Y22: 0 | Z22: 0 | AC22: 7816441 | AE22: PLAN DE PAGO | AF22: PHOENIX | AH22: CASTIGO | AI22: 56955195058 | AL22: vidal.gomez.elena.93@gmail.com | AO22: SANTA LAURA 1290 | AP22: MELIPILLA | AQ22: REGION METROPOLITANA | AR22: C-6723-2025 | AS22: 3º Juzgado Civil de Santiago | AT22: NOTIFICADO | AU22: MANTIENE | AZ22: SI | BA22: ACTIVO | BC22: SUZUKI | BD22: SWIFT 1.2 AMT GL SPORT | BE22: 0
A23: 3120521 | B23: 156 | D23: 15352634 | F23: PHOENIX | G23: JUDICIAL | H23: 0-365 | I23: 0-365 | J23: CASTIGO | K23: COBRANZA | L23: 46118 | N23: 6332455 | O23: 8 | P23: ELSA MARCIA DIAZ MORA | R23: 432150 | S23: 45962 | W23: TANNER | Y23: 0 | Z23: 0 | AC23: 15352634 | AE23: PLAN DE PAGO | AF23: PHOENIX | AH23: CASTIGO | AL23: DIAZVEGA82_@HOTMAIL.COM | AO23: PASAJE CORDILLERA CASA | AP23: ÑUBLE | AQ23: XIV REGION | AR23: C-2589-2025 | AS23: 5º Juzgado Civil de Santiago | AT23: INGRESADO | AU23: MANTIENE | AZ23: NO | BA23: ACTIVO | BC23: FOTON | BD23: G7 4x4 | BE23: 2024

Sheet TUBO VIGENTE JULIO
A1: CREDITO | B1: RUT | C1: NOMBRE | D1: TRAMO | E1: TRAMO ACTUAL | F1: TRAMO PEGA | G1: ESTADO_COBRANZA | H1: SOLUCION | I1: N° CUOTAS | J1: DIAS MORA | K1: VALOR CUOTA | L1: CAPITAL | M1: VALOR APROX DE PAGO | N1: FECHA COMPROMISO | O1: ESTADO | P1: FECHA PAGO | Q1: RECUPERADO | R1: OBSERVACIONES | S1: audios | T1: Oficio
A2: 2893403 | B2: =VLOOKUP(A2,Export!A:N,14,0) -> 10357961 | C2: =VLOOKUP(A2,Export!A:P,16,0) -> LUZ MARCELA LOPEZ BEAS | D2: =VLOOKUP(A2,Export!A:H,8,0) -> 91-120 | E2: =VLOOKUP(A2,Export!A:I,9,0) -> 61-90 | F2: 90+ | G2: =VLOOKUP(A2,Export!A:AH,34,0) -> BAJA90 | H2: PAGO CUOTAS | I2: 2 | J2: =VLOOKUP(A2,Export!A:B,2,0) -> 69 | K2: =VLOOKUP(A2,Export!A:R,18,0) -> 314.918 | L2: =VLOOKUP(A2,Export!A:D,4,0) -> 5770645 | M2: =IF(H2="PAGO CUOTAS",I2*K2,L2) -> 629.836 | N2: 46204 | O2: PAGADO | P2: 46204 | Q2: =+SUMIF(O2,"PAGADO",L2) -> 5770645 | R2: tt pago 1 y pagara otrael 15 y a fin de mes, 2do.pago 17/07 | S2: FALSE | T2: =VLOOKUP(A2,'OFICIO '!A:J,10,0) -> 46055
A3: 3251019 | B3: =VLOOKUP(A3,Export!A:N,14,0) -> 25890131 | C3: =VLOOKUP(A3,Export!A:P,16,0) -> JOSE JORGE COLORADO RODRIGUEZ | D3: =VLOOKUP(A3,Export!A:H,8,0) -> 61-90 | E3: =VLOOKUP(A3,Export!A:I,9,0) -> 61-90 | F3: C4 | G3: =VLOOKUP(A3,Export!A:AH,34,0) -> BAJA90 | H3: PAGO CUOTAS | I3: 1 | J3: =VLOOKUP(A3,Export!A:B,2,0) -> 71 | K3: =VLOOKUP(A3,Export!A:R,18,0) -> 373.22 | L3: =VLOOKUP(A3,Export!A:D,4,0) -> 9744091 | M3: =IF(H3="PAGO CUOTAS",I3*K3,L3) -> 373.22 | N3: 46205 | O3: PAGADO | P3: 46209 | Q3: =+SUMIF(O3,"PAGADO",L3) -> 9744091 | S3: FALSE | T3: =VLOOKUP(A3,'OFICIO '!A:J,10,0) -> #N/A
A4: 2914167 | B4: =VLOOKUP(A4,Export!A:N,14,0) -> 10585244 | C4: =VLOOKUP(A4,Export!A:P,16,0) -> CLAUDIA ORIETTA FREDES BARRERA | D4: =VLOOKUP(A4,Export!A:H,8,0) -> 31-60 | E4: =VLOOKUP(A4,Export!A:I,9,0) -> 61-90 | F4: C3 | G4: =VLOOKUP(A4,Export!A:AH,34,0) -> NO RECUPERADO | H4: PAGO CUOTAS | I4: 1 | J4: =VLOOKUP(A4,Export!A:B,2,0) -> 66 | K4: =VLOOKUP(A4,Export!A:R,18,0) -> 173.183 | L4: =VLOOKUP(A4,Export!A:D,4,0) -> 2641698 | M4: =IF(H4="PAGO CUOTAS",I4*K4,L4) -> 173.183 | N4: 46227 | O4: PENDIENTE | Q4: =+SUMIF(O4,"PAGADO",L4) -> 0 | S4: FALSE | T4: =VLOOKUP(A4,'OFICIO '!A:J,10,0) -> #N/A
A5: 2901204 | B5: =VLOOKUP(A5,Export!A:N,14,0) -> 14027161 | C5: =VLOOKUP(A5,Export!A:P,16,0) -> SAMUEL RODRIGO AGUILERA CARTER | D5: =VLOOKUP(A5,Export!A:H,8,0) -> 61-90 | E5: =VLOOKUP(A5,Export!A:I,9,0) -> 31-60 | F5: C4 | G5: =VLOOKUP(A5,Export!A:AH,34,0) -> BAJA90 | H5: PAGO CUOTAS | I5: 2 | J5: =VLOOKUP(A5,Export!A:B,2,0) -> 45 | K5: =VLOOKUP(A5,Export!A:R,18,0) -> 263.534 | L5: =VLOOKUP(A5,Export!A:D,4,0) -> 6922351 | M5: =IF(H5="PAGO CUOTAS",I5*K5,L5) -> 527.068 | N5: 46209 | O5: PAGADO | P5: 46209 | Q5: =+SUMIF(O5,"PAGADO",L5) -> 6922351 | S5: FALSE | T5: =VLOOKUP(A5,'OFICIO '!A:J,10,0) -> #N/A
A6: 2901203 | B6: =VLOOKUP(A6,Export!A:N,14,0) -> 19940769 | C6: =VLOOKUP(A6,Export!A:P,16,0) -> IGNACIO ALEJANDRO NAVARRETE DIAZ | D6: =VLOOKUP(A6,Export!A:H,8,0) -> 31-60 | E6: =VLOOKUP(A6,Export!A:I,9,0) -> 31-60 | F6: C3 | G6: =VLOOKUP(A6,Export!A:AH,34,0) -> CONTENIDO | H6: PAGO CUOTAS | I6: 1 | J6: =VLOOKUP(A6,Export!A:B,2,0) -> 45 | K6: =VLOOKUP(A6,Export!A:R,18,0) -> 325.481 | L6: =VLOOKUP(A6,Export!A:D,4,0) -> 5732485 | M6: =IF(H6="PAGO CUOTAS",I6*K6,L6) -> 325.481 | N6: 46205 | O6: PAGADO | P6: 46205 | Q6: =+SUMIF(O6,"PAGADO",L6) -> 5732485 | S6: FALSE | T6: =VLOOKUP(A6,'OFICIO '!A:J,10,0) -> #N/A
A7: 3334914 | B7: =VLOOKUP(A7,Export!A:N,14,0) -> 9507551 | C7: =VLOOKUP(A7,Export!A:P,16,0) -> JUAN LUIS HERNANDEZ ALMONACID | D7: =VLOOKUP(A7,Export!A:H,8,0) -> 121-150 | E7: =VLOOKUP(A7,Export!A:I,9,0) -> 151-180 | F7: 90+ | G7: =VLOOKUP(A7,Export!A:AH,34,0) -> NO RECUPERADO | H7: PAGO CUOTAS | I7: 5 | J7: =VLOOKUP(A7,Export!A:B,2,0) -> 165 | K7: =VLOOKUP(A7,Export!A:R,18,0) -> 367.186 | L7: =VLOOKUP(A7,Export!A:D,4,0) -> 10255953 | M7: =IF(H7="PAGO CUOTAS",I7*K7,L7) -> 1835.93 | N7: 46223 | O7: PENDIENTE | Q7: =+SUMIF(O7,"PAGADO",L7) -> 0 | S7: FALSE | T7: =VLOOKUP(A7,'OFICIO '!A:J,10,0) -> #N/A
A8: 2965293 | B8: =VLOOKUP(A8,Export!A:N,14,0) -> 9721000 | C8: =VLOOKUP(A8,Export!A:P,16,0) -> ELENA TERCIRA RIVAS JIMÉNEZ | D8: =VLOOKUP(A8,Export!A:H,8,0) -> 31-60 | E8: =VLOOKUP(A8,Export!A:I,9,0) -> 31-60 | F8: C3 | G8: =VLOOKUP(A8,Export!A:AH,34,0) -> CONTENIDO | H8: PAGO CUOTAS | I8: 1 | J8: =VLOOKUP(A8,Export!A:B,2,0) -> 40 | K8: =VLOOKUP(A8,Export!A:R,18,0) -> 359.588 | L8: =VLOOKUP(A8,Export!A:D,4,0) -> 8234831 | M8: =IF(H8="PAGO CUOTAS",I8*K8,L8) -> 359.588 | N8: 46207 | O8: PAGADO | Q8: =+SUMIF(O8,"PAGADO",L8) -> 8234831 | S8: FALSE | T8: =VLOOKUP(A8,'OFICIO '!A:J,10,0) -> #N/A
A9: 3159040 | B9: =VLOOKUP(A9,Export!A:N,14,0) -> 13872350 | C9: =VLOOKUP(A9,Export!A:P,16,0) -> ALEJANDRO PATRICIO NIETO SALFATE | D9: =VLOOKUP(A9,Export!A:H,8,0) -> 31-60 | E9: =VLOOKUP(A9,Export!A:I,9,0) -> 31-60 | F9: C3 | G9: =VLOOKUP(A9,Export!A:AH,34,0) -> CONTENIDO | H9: PAGO CUOTAS | I9: 1 | J9: =VLOOKUP(A9,Export!A:B,2,0) -> 34 | K9: =VLOOKUP(A9,Export!A:R,18,0) -> 510.567 | L9: =VLOOKUP(A9,Export!A:D,4,0) -> 15663717 | M9: =IF(H9="PAGO CUOTAS",I9*K9,L9) -> 510.567 | N9: 46206 | O9: PAGADO | P9: 46210 | Q9: =+SUMIF(O9,"PAGADO",L9) -> 15663717 | S9: FALSE | T9: =VLOOKUP(A9,'OFICIO '!A:J,10,0) -> #N/A
A10: 2926586 | B10: =VLOOKUP(A10,Export!A:N,14,0) -> 26071337 | C10: =VLOOKUP(A10,Export!A:P,16,0) -> WADSON CELESTIN | D10: =VLOOKUP(A10,Export!A:H,8,0) -> 121-150 | E10: =VLOOKUP(A10,Export!A:I,9,0) -> 91-120 | F10: 90+ | G10: =VLOOKUP(A10,Export!A:AH,34,0) -> CONTENIDO | H10: PAGO CUOTAS | I10: 3 | J10: =VLOOKUP(A10,Export!A:B,2,0) -> 106 | K10: =VLOOKUP(A10,Export!A:R,18,0) -> 98.892 | L10: =VLOOKUP(A10,Export!A:D,4,0) -> 1743128 | M10: =IF(H10="PAGO CUOTAS",I10*K10,L10) -> 296.676 | N10: 46206 | O10: PAGADO | Q10: =+SUMIF(O10,"PAGADO",L10) -> 1743128 | R10: trasf. M$250. pago 2 cuotas 15/07 | S10: FALSE | T10: =VLOOKUP(A10,'OFICIO '!A:J,10,0) -> #N/A
A11: 3524299 | B11: =VLOOKUP(A11,Export!A:N,14,0) -> 17174056 | C11: =VLOOKUP(A11,Export!A:P,16,0) -> JORGE JOEL IBÁÑEZ LÓPEZ | D11: =VLOOKUP(A11,Export!A:H,8,0) -> 61-90 | E11: =VLOOKUP(A11,Export!A:I,9,0) -> 46052 | F11: C4 | G11: =VLOOKUP(A11,Export!A:AH,34,0) -> BAJA90 | H11: PAGO CUOTAS | I11: 2 | J11: =VLOOKUP(A11,Export!A:B,2,0) -> 28 | K11: =VLOOKUP(A11,Export!A:R,18,0) -> 222.791 | L11: =VLOOKUP(A11,Export!A:D,4,0) -> 6436678 | M11: =IF(H11="PAGO CUOTAS",I11*K11,L11) -> 445.582 | N11: 46206 | O11: PAGADO | P11: 46210 | Q11: =+SUMIF(O11,"PAGADO",L11) -> 6436678 | S11: FALSE | T11: =VLOOKUP(A11,'OFICIO '!A:J,10,0) -> #N/A
A12: 2456670 | B12: =VLOOKUP(A12,Export!A:N,14,0) -> 26501219 | C12: =VLOOKUP(A12,Export!A:P,16,0) -> YERLAIN MARIA VILLALOBOS CAMACARO | D12: =VLOOKUP(A12,Export!A:H,8,0) -> 31-60 | E12: =VLOOKUP(A12,Export!A:I,9,0) -> 46052 | F12: C3 | G12: =VLOOKUP(A12,Export!A:AH,34,0) -> CONTENIDO | H12: PAGO CUOTAS | I12: 3 | J12: =VLOOKUP(A12,Export!A:B,2,0) -> 10 | K12: =VLOOKUP(A12,Export!A:R,18,0) -> 185.595 | L12: =VLOOKUP(A12,Export!A:D,4,0) -> 6715037 | M12: =IF(H12="PAGO CUOTAS",I12*K12,L12) -> 556.785 | N12: 46204 | O12: PAGADO | P12: 46210 | Q12: =+SUMIF(O12,"PAGADO",L12) -> 6715037 | S12: FALSE | T12: =VLOOKUP(A12,'OFICIO '!A:J,10,0) -> #N/A
A13: 3350049 | B13: =VLOOKUP(A13,Export!A:N,14,0) -> 15221775 | C13: =VLOOKUP(A13,Export!A:P,16,0) -> PAMELA ALEJANDRA GONZALEZ ALVAREZ | D13: =VLOOKUP(A13,Export!A:H,8,0) -> 151-180 | E13: =VLOOKUP(A13,Export!A:I,9,0) -> AL DIA | F13: 90+ | G13: =VLOOKUP(A13,Export!A:AH,34,0) -> BAJA90 | H13: PAGO CUOTAS | I13: 5 | J13: =VLOOKUP(A13,Export!A:B,2,0) -> 0 | K13: =VLOOKUP(A13,Export!A:R,18,0) -> 210.091 | L13: =VLOOKUP(A13,Export!A:D,4,0) -> 5661718 | M13: =IF(H13="PAGO CUOTAS",I13*K13,L13) -> 1050.455 | N13: 46206 | O13: PAGADO | Q13: =+SUMIF(O13,"PAGADO",L13) -> 5661718 | S13: FALSE | T13: =VLOOKUP(A13,'OFICIO '!A:J,10,0) -> #N/A
A14: 3456392 | B14: =VLOOKUP(A14,Export!A:N,14,0) -> 16406426 | C14: =VLOOKUP(A14,Export!A:P,16,0) -> MAURICIO ANDRÉS OLIVOS VILLALOBOS | D14: =VLOOKUP(A14,Export!A:H,8,0) -> 271-300 | E14: =VLOOKUP(A14,Export!A:I,9,0) -> 301-330 | F14: 90+ | G14: =VLOOKUP(A14,Export!A:AH,34,0) -> NO RECUPERADO | H14: PAGO CUOTAS | I14: 1 | J14: =VLOOKUP(A14,Export!A:B,2,0) -> 318 | K14: =VLOOKUP(A14,Export!A:R,18,0) -> 293.944 | L14: =VLOOKUP(A14,Export!A:D,4,0) -> 5914470 | M14: =IF(H14="PAGO CUOTAS",I14*K14,L14) -> 293.944 | N14: 46205 | O14: PENDIENTE | Q14: =+SUMIF(O14,"PAGADO",L14) -> 0 | S14: FALSE | T14: =VLOOKUP(A14,'OFICIO '!A:J,10,0) -> #N/A
A15: 2791803 | B15: =VLOOKUP(A15,Export!A:N,14,0) -> 15029397 | C15: =VLOOKUP(A15,Export!A:P,16,0) -> MARIA PIA ROJAS RAVEST | D15: =VLOOKUP(A15,Export!A:H,8,0) -> 31-60 | E15: =VLOOKUP(A15,Export!A:I,9,0) -> 61-90 | F15: C3 | G15: =VLOOKUP(A15,Export!A:AH,34,0) -> NO RECUPERADO | H15: PAGO CUOTAS | I15: 1 | J15: =VLOOKUP(A15,Export!A:B,2,0) -> 72 | K15: =VLOOKUP(A15,Export!A:R,18,0) -> 267.964 | L15: =VLOOKUP(A15,Export!A:D,4,0) -> 5749965 | M15: =IF(H15="PAGO CUOTAS",I15*K15,L15) -> 267.964 | N15: 46233 | O15: PENDIENTE | Q15: =+SUMIF(O15,"PAGADO",L15) -> 0 | S15: FALSE | T15: =VLOOKUP(A15,'OFICIO '!A:J,10,0) -> #N/A
A16: 3291352 | B16: =VLOOKUP(A16,Export!A:N,14,0) -> 11378450 | C16: =VLOOKUP(A16,Export!A:P,16,0) -> MARCO ANTONIO NATIVIA ESCALERA | D16: =VLOOKUP(A16,Export!A:H,8,0) -> 151-180 | E16: =VLOOKUP(A16,Export!A:I,9,0) -> 31-60 | F16: 90+ | G16: =VLOOKUP(A16,Export!A:AH,34,0) -> BAJA90 | H16: PAGO CUOTAS | I16: 4 | J16: =VLOOKUP(A16,Export!A:B,2,0) -> 53 | K16: =VLOOKUP(A16,Export!A:R,18,0) -> 147.577 | L16: =VLOOKUP(A16,Export!A:D,4,0) -> 4680147 | M16: =IF(H16="PAGO CUOTAS",I16*K16,L16) -> 590.308 | N16: 46205 | O16: PAGADO | Q16: =+SUMIF(O16,"PAGADO",L16) -> 4680147 | S16: FALSE | T16: =VLOOKUP(A16,'OFICIO '!A:J,10,0) -> #N/A
A17: 3089537 | B17: =VLOOKUP(A17,Export!A:N,14,0) -> 14530681 | C17: =VLOOKUP(A17,Export!A:P,16,0) -> INGRID ALEJANDRA SANDOVAL MARDONES | D17: =VLOOKUP(A17,Export!A:H,8,0) -> 61-90 | E17: =VLOOKUP(A17,Export!A:I,9,0) -> 61-90 | F17: C4 | G17: =VLOOKUP(A17,Export!A:AH,34,0) -> BAJA90 | H17: PAGO CUOTAS | I17: 1 | J17: =VLOOKUP(A17,Export!A:B,2,0) -> 66 | K17: =VLOOKUP(A17,Export!A:R,18,0) -> 322.279 | L17: =VLOOKUP(A17,Export!A:D,4,0) -> 7477518 | M17: =IF(H17="PAGO CUOTAS",I17*K17,L17) -> 322.279 | N17: 46204 | O17: PAGADO | P17: 46204 | Q17: =+SUMIF(O17,"PAGADO",L17) -> 7477518 | S17: FALSE | T17: =VLOOKUP(A17,'OFICIO '!A:J,10,0) -> #N/A
A18: 2820080 | B18: =VLOOKUP(A18,Export!A:N,14,0) -> 14570180 | C18: =VLOOKUP(A18,Export!A:P,16,0) -> HIFFYT MARLENE AGUILERA PEREZ | D18: =VLOOKUP(A18,Export!A:H,8,0) -> 61-90 | E18: =VLOOKUP(A18,Export!A:I,9,0) -> 31-60 | F18: C4 | G18: =VLOOKUP(A18,Export!A:AH,34,0) -> BAJA90 | H18: PAGO CUOTAS | I18: 2 | J18: =VLOOKUP(A18,Export!A:B,2,0) -> 45 | K18: =VLOOKUP(A18,Export!A:R,18,0) -> 360.517 | L18: =VLOOKUP(A18,Export!A:D,4,0) -> 3173278 | M18: =IF(H18="PAGO CUOTAS",I18*K18,L18) -> 721.034 | O18: PAGADO | Q18: =+SUMIF(O18,"PAGADO",L18) -> 3173278 | R18: 15/07 y 30/07 paga 1 cuota + | S18: FALSE | T18: =VLOOKUP(A18,'OFICIO '!A:J,10,0) -> #N/A
A19: 2822126 | B19: =VLOOKUP(A19,Export!A:N,14,0) -> 17484621 | C19: =VLOOKUP(A19,Export!A:P,16,0) -> PRISCILLA FERNANDA SALDÍAS BARROS | D19: =VLOOKUP(A19,Export!A:H,8,0) -> 61-90 | E19: =VLOOKUP(A19,Export!A:I,9,0) -> 46052 | F19: C4 | G19: =VLOOKUP(A19,Export!A:AH,34,0) -> BAJA90 | H19: PAGO CUOTAS | I19: 2 | J19: =VLOOKUP(A19,Export!A:B,2,0) -> 30 | K19: =VLOOKUP(A19,Export!A:R,18,0) -> 170.887 | L19: =VLOOKUP(A19,Export!A:D,4,0) -> 2494587 | M19: =IF(H19="PAGO CUOTAS",I19*K19,L19) -> 341.774 | N19: 46205 | O19: PAGADO | P19: 46205 | Q19: =+SUMIF(O19,"PAGADO",L19) -> 2494587 | S19: FALSE | T19: =VLOOKUP(A19,'OFICIO '!A:J,10,0) -> #N/A
A20: 2381394 | B20: =VLOOKUP(A20,Export!A:N,14,0) -> 13875254 | C20: =VLOOKUP(A20,Export!A:P,16,0) -> CARLA ORIANA MUÑOZ MIRANDA | D20: =VLOOKUP(A20,Export!A:H,8,0) -> 61-90 | E20: =VLOOKUP(A20,Export!A:I,9,0) -> 31-60 | F20: C4 | G20: =VLOOKUP(A20,Export!A:AH,34,0) -> BAJA90 | H20: PAGO CUOTAS | I20: 1 | J20: =VLOOKUP(A20,Export!A:B,2,0) -> 58 | K20: =VLOOKUP(A20,Export!A:R,18,0) -> 378.731 | L20: =VLOOKUP(A20,Export!A:D,4,0) -> 3575169 | M20: =IF(H20="PAGO CUOTAS",I20*K20,L20) -> 378.731 | N20: 46204 | O20: PAGADO | P20: 46204 | Q20: =+SUMIF(O20,"PAGADO",L20) -> 3575169 | S20: FALSE | T20: =VLOOKUP(A20,'OFICIO '!A:J,10,0) -> #N/A
A21: 2545904 | B21: =VLOOKUP(A21,Export!A:N,14,0) -> 13011353 | C21: =VLOOKUP(A21,Export!A:P,16,0) -> MAURICIO ALEJANDRO DIAZ CARRIZO | D21: =VLOOKUP(A21,Export!A:H,8,0) -> 31-60 | E21: =VLOOKUP(A21,Export!A:I,9,0) -> 31-60 | F21: C3 | G21: =VLOOKUP(A21,Export!A:AH,34,0) -> CONTENIDO | H21: PAGO CUOTAS | I21: 2 | J21: =VLOOKUP(A21,Export!A:B,2,0) -> 45 | K21: =VLOOKUP(A21,Export!A:R,18,0) -> 189.035 | L21: =VLOOKUP(A21,Export!A:D,4,0) -> 4134127 | M21: =IF(H21="PAGO CUOTAS",I21*K21,L21) -> 378.07 | N21: 46209 | O21: PAGADO | Q21: =+SUMIF(O21,"PAGADO",L21) -> 4134127 | S21: FALSE | T21: =VLOOKUP(A21,'OFICIO '!A:J,10,0) -> #N/A
A22: 2993173 | B22: =VLOOKUP(A22,Export!A:N,14,0) -> 13217975 | C22: =VLOOKUP(A22,Export!A:P,16,0) -> FERNANDO RAÚL FERNÁNDEZ ZAVALA | D22: =VLOOKUP(A22,Export!A:H,8,0) -> 211-240 | E22: =VLOOKUP(A22,Export!A:I,9,0) -> 241-270 | F22: 90+ | G22: =VLOOKUP(A22,Export!A:AH,34,0) -> NO RECUPERADO | H22: PAGO CUOTAS | I22: 6 | J22: =VLOOKUP(A22,Export!A:B,2,0) -> 251 | K22: =VLOOKUP(A22,Export!A:R,18,0) -> 304.433 | L22: =VLOOKUP(A22,Export!A:D,4,0) -> 4482749 | M22: =IF(H22="PAGO CUOTAS",I22*K22,L22) -> 1826.598 | N22: 46234 | O22: PAGADO | Q22: =+SUMIF(O22,"PAGADO",L22) -> 4482749 | R22: transferencia M$2098. | S22: FALSE | T22: =VLOOKUP(A22,'OFICIO '!A:J,10,0) -> #N/A
A23: 2567747 | B23: =VLOOKUP(A23,Export!A:N,14,0) -> 23109537 | C23: =VLOOKUP(A23,Export!A:P,16,0) -> BRAYAN GIAMPIER BAZAN VIGO | D23: =VLOOKUP(A23,Export!A:H,8,0) -> 181-210 | E23: =VLOOKUP(A23,Export!A:I,9,0) -> 211-240 | F23: 90+ | G23: =VLOOKUP(A23,Export!A:AH,34,0) -> NO RECUPERADO | H23: PAGO CUOTAS | I23: 5 | J23: =VLOOKUP(A23,Export!A:B,2,0) -> 222 | K23: =VLOOKUP(A23,Export!A:R,18,0) -> 383.307 | L23: =VLOOKUP(A23,Export!A:D,4,0) -> 9087248 | M23: =IF(H23="PAGO CUOTAS",I23*K23,L23) -> 1916.535 | N23: 46218 | O23: PENDIENTE | Q23: =+SUMIF(O23,"PAGADO",L23) -> 0 | S23: FALSE | T23: =VLOOKUP(A23,'OFICIO '!A:J,10,0) -> #N/A
A24: 2877820 | B24: =VLOOKUP(A24,Export!A:N,14,0) -> 7896030 | C24: =VLOOKUP(A24,Export!A:P,16,0) -> MIGUEL ANGEL CAMPOS CID | D24: =VLOOKUP(A24,Export!A:H,8,0) -> 61-90 | E24: =VLOOKUP(A24,Export!A:I,9,0) -> 61-90 | F24: C4 | G24: =VLOOKUP(A24,Export!A:AH,34,0) -> BAJA90 | H24: PAGO CUOTAS | I24: 1 | J24: =VLOOKUP(A24,Export!A:B,2,0) -> 74 | K24: =VLOOKUP(A24,Export!A:R,18,0) -> 336.651 | L24: =VLOOKUP(A24,Export!A:D,4,0) -> 5841087 | M24: =IF(H24="PAGO CUOTAS",I24*K24,L24) -> 336.651 | N24: 46209 | O24: PAGADO | P24: 46209 | Q24: =+SUMIF(O24,"PAGADO",L24) -> 5841087 | S24: FALSE | T24: =VLOOKUP(A24,'OFICIO '!A:J,10,0) -> #N/A
A25: 2003692 | B25: =VLOOKUP(A25,Export!A:N,14,0) -> 11527231 | C25: =VLOOKUP(A25,Export!A:P,16,0) -> LAURA DEL CARMEN SOTO BARRÍA | D25: =VLOOKUP(A25,Export!A:H,8,0) -> 151-180 | E25: =VLOOKUP(A25,Export!A:I,9,0) -> 61-90 | F25: 90+ | G25: =VLOOKUP(A25,Export!A:AH,34,0) -> CONTENIDO | H25: PAGO CUOTAS | I25: 4 | J25: =VLOOKUP(A25,Export!A:B,2,0) -> 89 | K25: =VLOOKUP(A25,Export!A:R,18,0) -> 399.393 | L25: =VLOOKUP(A25,Export!A:D,4,0) -> 2205064 | M25: =IF(H25="PAGO CUOTAS",I25*K25,L25) -> 1597.572 | N25: 46216 | O25: PAGADO | Q25: =+SUMIF(O25,"PAGADO",L25) -> 2205064 | S25: FALSE | T25: =VLOOKUP(A25,'OFICIO '!A:J,10,0) -> #N/A
A26: 3346863 | B26: =VLOOKUP(A26,Export!A:N,14,0) -> 8331309 | C26: =VLOOKUP(A26,Export!A:P,16,0) -> MÓNICA ELIZABETH LINEROS FUENTES | D26: =VLOOKUP(A26,Export!A:H,8,0) -> 61-90 | E26: =VLOOKUP(A26,Export!A:I,9,0) -> 91-120 | F26: C4 | G26: =VLOOKUP(A26,Export!A:AH,34,0) -> NO RECUPERADO | H26: PAGO CUOTAS | I26: 2 | J26: =VLOOKUP(A26,Export!A:B,2,0) -> 97 | K26: =VLOOKUP(A26,Export!A:R,18,0) -> 344.975 | L26: =VLOOKUP(A26,Export!A:D,4,0) -> 10062772 | M26: =IF(H26="PAGO CUOTAS",I26*K26,L26) -> 689.95 | N26: 46233 | O26: PENDIENTE | Q26: =+SUMIF(O26,"PAGADO",L26) -> 0 | S26: FALSE | T26: =VLOOKUP(A26,'OFICIO '!A:J,10,0) -> #N/A
A27: 1769482 | B27: =VLOOKUP(A27,Export!A:N,14,0) -> 16986051 | C27: =VLOOKUP(A27,Export!A:P,16,0) -> CARLOS ANDRES POLANCO DIAZ | D27: =VLOOKUP(A27,Export!A:H,8,0) -> 211-240 | E27: =VLOOKUP(A27,Export!A:I,9,0) -> 241-270 | F27: 90+ | G27: =VLOOKUP(A27,Export!A:AH,34,0) -> NO RECUPERADO | H27: PREPAGO | J27: =VLOOKUP(A27,Export!A:B,2,0) -> 252 | K27: =VLOOKUP(A27,Export!A:R,18,0) -> 336.303 | L27: =VLOOKUP(A27,Export!A:D,4,0) -> 4635527 | M27: =IF(H27="PAGO CUOTAS",I27*K27,L27) -> 4635527 | N27: 46234 | O27: PENDIENTE | Q27: =+SUMIF(O27,"PAGADO",L27) -> 0 | S27: FALSE | T27: =VLOOKUP(A27,'OFICIO '!A:J,10,0) -> #N/A
